Connected to database: sqlite:///federated_learning.db
2025-02-28 16:25:40.214 Examining the path of torch.classes raised:
Traceback (most recent call last):
  File "/home/runner/workspace/.pythonlibs/lib/python3.12/site-packages/streamlit/web/bootstrap.py", line 345, in run
    if asyncio.get_running_loop().is_running():
       ^^^^^^^^^^^^^^^^^^^^^^^^^^
RuntimeError: no running event loop

During handling of the above exception, another exception occurred:

Traceback (most recent call last):
  File "/home/runner/workspace/.pythonlibs/lib/python3.12/site-packages/streamlit/watcher/local_sources_watcher.py", line 217, in get_module_paths
    potential_paths = extract_paths(module)
                      ^^^^^^^^^^^^^^^^^^^^^
  File "/home/runner/workspace/.pythonlibs/lib/python3.12/site-packages/streamlit/watcher/local_sources_watcher.py", line 210, in <lambda>
    lambda m: list(m.__path__._path),
                   ^^^^^^^^^^^^^^^^
  File "/home/runner/workspace/.pythonlibs/lib/python3.12/site-packages/torch/_classes.py", line 13, in __getattr__
    proxy = torch._C._get_custom_class_python_wrapper(self.name, attr)
            ^^^^^^^^^^^^^^^^^^^^^^^^^^^^^^^^^^^^^^^^^^^^^^^^^^^^^^^^^^
RuntimeError: Tried to instantiate class '__path__._path', but it does not exist! Ensure that it is registered via torch::class_
2025-02-28 16:27:14.313 Examining the path of torch.classes raised:
Traceback (most recent call last):
  File "/home/runner/workspace/.pythonlibs/lib/python3.12/site-packages/streamlit/web/bootstrap.py", line 345, in run
    if asyncio.get_running_loop().is_running():
       ^^^^^^^^^^^^^^^^^^^^^^^^^^
RuntimeError: no running event loop

During handling of the above exception, another exception occurred:

Traceback (most recent call last):
  File "/home/runner/workspace/.pythonlibs/lib/python3.12/site-packages/streamlit/watcher/local_sources_watcher.py", line 217, in get_module_paths
    potential_paths = extract_paths(module)
                      ^^^^^^^^^^^^^^^^^^^^^
  File "/home/runner/workspace/.pythonlibs/lib/python3.12/site-packages/streamlit/watcher/local_sources_watcher.py", line 210, in <lambda>
    lambda m: list(m.__path__._path),
                   ^^^^^^^^^^^^^^^^
  File "/home/runner/workspace/.pythonlibs/lib/python3.12/site-packages/torch/_classes.py", line 13, in __getattr__
    proxy = torch._C._get_custom_class_python_wrapper(self.name, attr)
            ^^^^^^^^^^^^^^^^^^^^^^^^^^^^^^^^^^^^^^^^^^^^^^^^^^^^^^^^^^
RuntimeError: Tried to instantiate class '__path__._path', but it does not exist! Ensure that it is registered via torch::class_
2025-02-28 16:27:49.277 Examining the path of torch.classes raised:
Traceback (most recent call last):
  File "/home/runner/workspace/.pythonlibs/lib/python3.12/site-packages/streamlit/web/bootstrap.py", line 345, in run
    if asyncio.get_running_loop().is_running():
       ^^^^^^^^^^^^^^^^^^^^^^^^^^
RuntimeError: no running event loop

During handling of the above exception, another exception occurred:

Traceback (most recent call last):
  File "/home/runner/workspace/.pythonlibs/lib/python3.12/site-packages/streamlit/watcher/local_sources_watcher.py", line 217, in get_module_paths
    potential_paths = extract_paths(module)
                      ^^^^^^^^^^^^^^^^^^^^^
  File "/home/runner/workspace/.pythonlibs/lib/python3.12/site-packages/streamlit/watcher/local_sources_watcher.py", line 210, in <lambda>
    lambda m: list(m.__path__._path),
                   ^^^^^^^^^^^^^^^^
  File "/home/runner/workspace/.pythonlibs/lib/python3.12/site-packages/torch/_classes.py", line 13, in __getattr__
    proxy = torch._C._get_custom_class_python_wrapper(self.name, attr)
            ^^^^^^^^^^^^^^^^^^^^^^^^^^^^^^^^^^^^^^^^^^^^^^^^^^^^^^^^^^
RuntimeError: Tried to instantiate class '__path__._path', but it does not exist! Ensure that it is registered via torch::class_
